<?xml version="1.0"?>

<!-- 

# ===================================== COPYRIGHT ===================================== #
#                                                                                       #
#  IFRA (Intelligent Flexible Robotics and Assembly) Group, CRANFIELD UNIVERSITY        #
#  Created on behalf of the IFRA Group at Cranfield University, United Kingdom          #
#  E-mail: IFRA@cranfield.ac.uk                                                         #
#                                                                                       #
#  Licensed under the Apache-2.0 License.                                               #
#  You may not use this file except in compliance with the License.                     #
#  You may obtain a copy of the License at: http://www.apache.org/licenses/LICENSE-2.0  #
#                                                                                       #
#  Unless required by applicable law or agreed to in writing, software distributed      #
#  under the License is distributed on an "as-is" basis, without warranties or          #
#  conditions of any kind, either express or implied. See the License for the specific  #
#  language governing permissions and limitations under the License.                    #
#                                                                                       #
#  IFRA Group - Cranfield University                                                    #
#  AUTHORS: Mikel Bueno Viso - Mikel.Bueno-Viso@cranfield.ac.uk                         #
#           Seemal Asif      - s.asif@cranfield.ac.uk                                   #
#           Phil Webb        - p.f.webb@cranfield.ac.uk                                 #
#                                                                                       #
#  Date: July, 2022.                                                                    #
#                                                                                       #
# ===================================== COPYRIGHT ===================================== #

# ===================================== COPYRIGHT ===================================== #
#                                                                                       #
#  Some of the information used to build the ROS2 ABB-IRB120 .urdf files in this ROS2   #
#  repository has been taken from the following resource:                               #
#       - abb_experimental (https://github.com/ros-industrial/abb_experimental)         #
#                                                                                       #
#  AUTHORS:                                                                             #
#       - ROS-Industrial - https://rosindustrial.org                                    #
#       - Mark Culleton (Trinity College Dublin) - culletom@tcd.ie                      #
#       - Kevin Kelly   (Trinity College Dublin)                                        #
#                                                                                       #
#  COPYRIGHT - ROS-Industrial                                                           #
#  (ORIGINAL LICENSE) -> Licensed under the Apache-2.0 License.                         #
#                                                                                       #
#  CHANGES MADE:                                                                        #
#  The original files contain the .urdf information of the robot for ROS1, and these    #
#  have been modified for ROS2.                                                         #
#                                                                                       #
# ===================================== COPYRIGHT ===================================== #

# ======= CITE OUR WORK ======= #
# You can cite our work with the following statement:
# IFRA (2022) ROS2.0 ROBOT SIMULATION. URL: https://github.com/IFRA-Cranfield/ros2_RobotSimulation.

-->

<robot xmlns:xacro="http://ros.org/wiki/xacro">
  
  <!-- Include additional ABB-Resources/MATERIALS+COLOUR xacro files: -->
  <xacro:include filename="$(find irb120_ros2_gazebo)/urdf/abb_resources/common_materials.xacro"/>

  <!-- XACRO-MACRO of ABB-IRB120: -->
  <xacro:macro name="irb120" params="prefix EE_no EE_schunk">

    <!-- Load ABB IRB120 TRANSMISSION file: -->
    <xacro:include filename="$(find irb120_ros2_gazebo)/urdf/irb120_transmission.xacro" />
    <xacro:irb120_transmission 
      prefix=""
      EE_schunk="${EE_schunk}"
    />
    
    <!-- Load ABB IRB120 ROS2_CONTROL file: -->
    <xacro:include filename="$(find irb120_ros2_gazebo)/urdf/irb120_ros2control.xacro" />
    <xacro:irb120_ros2control 
      prefix=""
      EE_no="${EE_no}"
      EE_schunk="${EE_schunk}"
    />

    <!-- ***** ABB-IRB120 ROBOT .urdf SERIAL CHAIN ***** -->

    <!-- Link list: -->
    <!-- base_link -->
    <link name="${prefix}base_link">
      <inertial>
        <mass value="6.215"/>
        <origin xyz="-0.04204 8.01E-05 0.07964" rpy="0 0 0"/>
        <inertia ixx="0.0247272" ixy="-8.0784E-05" ixz="0.00130902" iyy="0.0491285" iyz="-8.0419E-06" izz="0.0472376"/>
      </inertial>
      <visual>
        <origin xyz="0 0 0" rpy="0 0 0"/>
        <geometry>
          <mesh filename="file://$(find irb120_ros2_gazebo)/meshes/visual/base_link.stl"/>
        </geometry>
        <xacro:material_abb_orange />
      </visual>
      <collision>
        <origin xyz="0 0 0" rpy="0 0 0"/>
        <geometry>
          <mesh filename="file://$(find irb120_ros2_gazebo)/meshes/collision/base_link.stl"/>
        </geometry>
        <xacro:material_abb_yellow />
      </collision>
    </link>

    <!-- link_1 -->
    <link name="${prefix}link_1">
      <inertial>
        <mass value="3.067" />
        <origin xyz="9.77E-05 -0.00012 0.23841" rpy="0 0 0"/>
        <inertia ixx="0.0142175" ixy="-1.28579E-05" ixz="-2.31364E-05" iyy="0.0144041" iyz="1.93404E-05" izz="0.0104533"/>
      </inertial>
      <visual>
        <origin xyz="0 0 0" rpy="0 0 0"/>
        <geometry>
          <mesh filename="file://$(find irb120_ros2_gazebo)/meshes/visual/link_1.stl"/>
        </geometry>
        <xacro:material_abb_orange />
      </visual>
      <collision>
        <origin xyz="0 0 0" rpy="0 0 0"/>
        <geometry>
          <mesh filename="file://$(find irb120_ros2_gazebo)/meshes/collision/link_1.stl"/>
        </geometry>
        <xacro:material_abb_yellow />
      </collision>
    </link>

    <!-- link_2 -->
    <link name="${prefix}link_2">
      <inertial>
        <mass value="3.909"/>
        <origin xyz="0.00078 -0.00212 0.10124" rpy="0 0 0"/>
        <inertia ixx="0.0603111" ixy="9.83431E-06" ixz="5.72407E-05" iyy="0.041569" iyz="-0.00050497" izz="0.0259548"/>
      </inertial>
      <visual>
        <origin xyz="0 0 0" rpy="0 0 0"/>
        <geometry>
          <mesh filename="file://$(find irb120_ros2_gazebo)/meshes/visual/link_2.stl"/>
        </geometry>
        <xacro:material_abb_orange />
      </visual>
      <collision>
        <origin xyz="0 0 0" rpy="0 0 0"/>
        <geometry>
          <mesh filename="file://$(find irb120_ros2_gazebo)/meshes/collision/link_2.stl"/>
        </geometry>
        <xacro:material_abb_yellow />
      </collision>
    </link>

    <!-- link_3 -->
    <link name="${prefix}link_3">
      <inertial>
        <mass value="2.944"/>
        <origin xyz="0.02281 0.00106 0.05791" rpy="0 0 0"/>
        <inertia ixx="0.00835606" ixy="-8.01545E-05" ixz="0.00142884" iyy="0.016713" iyz="-0.000182227" izz="0.0126984"/>
      </inertial>
      <visual>
        <origin xyz="0 0 0" rpy="0 0 0"/>
        <geometry>
          <mesh filename="file://$(find irb120_ros2_gazebo)/meshes/visual/link_3.stl"/>
        </geometry>
        <xacro:material_abb_orange />
      </visual>
      <collision>
        <origin xyz="0 0 0" rpy="0 0 0"/>
        <geometry>
          <mesh filename="file://$(find irb120_ros2_gazebo)/meshes/collision/link_3.stl"/>
        </geometry>
        <xacro:material_abb_yellow />
      </collision>
    </link>

    <!-- link_4 -->
    <link name="${prefix}link_4">
      <inertial>
        <mass value="1.328"/>
        <origin xyz="0.2247 0.00015 0.00041" rpy="0 0 0"/>
        <inertia ixx="0.00284661" ixy="-2.12765E-05" ixz="-1.6435E-05" iyy="0.00401346" iyz="1.31336E-05" izz="0.0052535"/>
      </inertial>
      <visual>
        <origin xyz="0 0 0" rpy="0 0 0"/>
        <geometry>
          <mesh filename="file://$(find irb120_ros2_gazebo)/meshes/visual/link_4.stl"/>
        </geometry>
        <xacro:material_abb_orange />
      </visual>
      <collision>
        <origin xyz="0 0 0" rpy="0 0 0"/>
        <geometry>
          <mesh filename="file://$(find irb120_ros2_gazebo)/meshes/collision/link_4.stl"/>
        </geometry>
        <xacro:material_abb_yellow />
      </collision>
    </link>

    <!-- link_5 -->
    <link name="${prefix}link_5">
      <inertial>
        <mass value="0.546"/>
        <origin xyz="-0.00109 3.68E-05 6.22E-05" rpy="0 0 0"/>
        <inertia ixx="0.000404891" ixy="1.61943E-06" ixz="8.46805E-07" iyy="0.000892825" iyz="-1.51792E-08" izz="0.000815468"/>
      </inertial>
      <visual>
        <origin xyz="0 0 0" rpy="0 0 0"/>
        <geometry>
          <mesh filename="file://$(find irb120_ros2_gazebo)/meshes/visual/link_5.stl"/>
        </geometry>
        <xacro:material_abb_orange />
      </visual>
      <collision>
        <origin xyz="0 0 0" rpy="0 0 0"/>
        <geometry>
          <mesh filename="file://$(find irb120_ros2_gazebo)/meshes/collision/link_5.stl"/>
        </geometry>
        <xacro:material_abb_yellow />
      </collision>
    </link>

    <!-- link_6 -->
    <link name="${prefix}link_6">
      <inertial>
        <mass value="0.137"/>
        <origin xyz="-0.00706 -0.00017 -1.32E-06" rpy="0 0 0"/>
        <inertia ixx="0.001" ixy="0" ixz="0" iyy="0.001" iyz="0" izz="0.001"/>
      </inertial>
      <visual>
        <origin xyz="0 0 0" rpy="0 0 0"/>
        <geometry>
          <mesh filename="file://$(find irb120_ros2_gazebo)/meshes/visual/link_6.stl"/>
        </geometry>
        <xacro:material_abb_black />
      </visual>
      <collision>
        <origin xyz="0 0 0" rpy="0 0 0"/>
        <geometry>
          <mesh filename="file://$(find irb120_ros2_gazebo)/meshes/collision/link_6.stl"/>
        </geometry>
        <xacro:material_abb_yellow />
      </collision>
    </link>
    <!-- end of link list -->

    <!-- Joint list: -->
    <!-- joint_1 -->
    <joint name="${prefix}joint_1" type="revolute">
      <origin rpy="0 0 0" xyz="0 0 0"/>
      <parent link="${prefix}base_link"/>
      <child link="${prefix}link_1"/>
      <limit effort="0" lower="-2.87979" upper="2.87979" velocity="4.36332"/>
      <axis xyz="0 0 1"/>
      <dynamics damping="0.0" friction="0.0"/>
    </joint>

    <!-- joint_2 -->
    <joint name="${prefix}joint_2" type="revolute">
      <origin rpy="0 0 0" xyz="0 0 0.29"/>
      <parent link="${prefix}link_1"/>
      <child link="${prefix}link_2"/>
      <limit effort="0" lower="-1.91986" upper="1.91986" velocity="4.36332"/>
      <axis xyz="0 1 0"/>
      <dynamics damping="0.0" friction="0.0"/>
    </joint>

    <!-- joint_3 -->
    <joint name="${prefix}joint_3" type="revolute">
      <origin rpy="0 0 0" xyz="0 0 0.27"/>
      <parent link="${prefix}link_2"/>
      <child link="${prefix}link_3"/>
      <limit effort="0" lower="-1.91986" upper="1.22173" velocity="4.36332"/>
      <axis xyz="0 1 0"/>
      <dynamics damping="0.0" friction="0.0"/>
    </joint>

    <!-- joint_4 -->
    <joint name="${prefix}joint_4" type="revolute">
      <origin rpy="0 0 0" xyz="0 0 0.07"/>
      <parent link="${prefix}link_3"/>
      <child link="${prefix}link_4"/>
      <limit effort="0" lower="-2.79253" upper="2.79253" velocity="5.58505"/>
      <axis xyz="1 0 0"/>
      <dynamics damping="0.0" friction="0.0"/>
    </joint>

    <!-- joint_5 -->
    <joint name="${prefix}joint_5" type="revolute">
      <origin rpy="0 0 0" xyz="0.302 0 0"/>
      <parent link="${prefix}link_4"/>
      <child link="${prefix}link_5"/>
      <limit effort="0" lower="-2.094395" upper="2.094395" velocity="5.58505"/>
      <axis xyz="0 1 0"/>
      <dynamics damping="0.0" friction="0.0"/>
    </joint>

    <!-- joint_6 -->
    <joint name="${prefix}joint_6" type="revolute">
      <origin rpy="0 0 0" xyz="0.072 0 0"/>
      <parent link="${prefix}link_5"/>
      <child link="${prefix}link_6"/>
      <limit effort="0" lower="-6.98132" upper="6.98132" velocity="7.33038"/>
      <axis xyz="1 0 0"/>
      <dynamics damping="0.0" friction="0.0"/>
    </joint>
    <!-- end of joint list -->

    <!-- ROS-Industrial 'base' frame: base_link to ABB World Coordinates transform -->
    <link name="${prefix}base" />
    <joint name="${prefix}base_link-base" type="fixed">
      <origin xyz="0 0 0" rpy="0 0 0"/>
      <parent link="${prefix}base_link"/>
      <child link="${prefix}base"/>
    </joint>

    <!-- ROS-Industrial 'flange' frame: attachment point for EEF models -->
    <link name="${prefix}flange"/>
    <joint type="fixed" name="${prefix}joint_6-flange">
      <origin xyz="0 0 0" rpy="0 0 0"/>
      <parent link="${prefix}link_6"/>
      <child link="${prefix}flange"/>
    </joint>

    <!-- ROS-Industrial 'tool0' frame: all-zeros tool frame -->
    <link name="${prefix}tool0" />
    <joint name="${prefix}link_6-tool0" type="fixed">
      <origin xyz="0 0 0" rpy="0 ${radians(90)} 0" />
      <parent link="${prefix}flange" />
      <child link="${prefix}tool0" />
    </joint>

    <!-- =================================== -->
    <!-- ========== END-EFFECTORS ========== -->

    <!-- === SCHUNK EGP-64 GRIPPER === -->
    <xacro:if value="${EE_schunk}">

      <!-- Schunk coupler (LINK): -->
      <link name="schunk_coupler">
        <visual>
          <geometry>
            <mesh filename="file://$(find irb120_ros2_gazebo)/meshes/egp64/Schunk Gripper - ADAPTER.dae" />
          </geometry>
        </visual>
        <collision>
          <geometry>
            <mesh filename="file://$(find irb120_ros2_gazebo)/meshes/egp64/Schunk Gripper - ADAPTER.dae" />
          </geometry>
        </collision>
        <inertial>
          <origin xyz="0 0 0" rpy="0 0 ${pi/4}" />
          <mass value="0.001" />
          <inertia ixx="0.001" ixy="0.0" ixz="0.0" iyy="0.001" iyz="0.0" izz="0.001"/>
        </inertial>
      </link>

      <!-- Schunk coupler (JOINT): -->
      <joint name="schunk_coupler_joint" type="fixed">
        <origin xyz="0 0 0.001" rpy="0 0 ${pi/4}" />
        <parent link="tool0"/>
        <child link="schunk_coupler"/>
      </joint>
      <gazebo reference="schunk_coupler">
        <mu1>0.9</mu1>
        <mu2>0.9</mu2>
        <material>Gazebo/Black</material>
      </gazebo>

      <link name="egp64_gripper_base_link">
        <inertial>
          <origin xyz="0 0 0" rpy="0 0 0" />
          <mass value="0.005" />
          <inertia ixx="0.001" ixy="0.0" ixz="0.0" iyy="0.001" iyz="0.0" izz="0.001"/>
        </inertial>
        <visual>
          <geometry>
            <mesh filename="file://$(find irb120_ros2_gazebo)/meshes/egp64/Schunk Gripper - BASE noAdapter.dae" />
          </geometry>
          <material name="blue">
            <color rgba="0 0 1 1"/>
          </material>
        </visual>
        <collision>
          <geometry>
            <mesh filename="file://$(find irb120_ros2_gazebo)/meshes/egp64/Schunk Gripper - BASE noAdapter.dae" />
          </geometry>
          <material name="blue"/>
        </collision>
      </link>

      <joint name="egp64_coupler" type="fixed">
        <parent link="schunk_coupler"/>
        <child link="egp64_gripper_base_link"/>
        <origin xyz="-0.03205 0.01812 0.02047" rpy="0 0 0" />
      </joint>

      <!-- LEFT FINGER BASE -->
      
      <link name="egp64_finger_left_link">
        <inertial>
          <origin xyz="0.01483 -0.00782 0" rpy="0 0 0" />
          <mass value="0.002" />
          <inertia ixx="0.001" ixy="0.0" ixz="0.0" iyy="0.001" iyz="0.0" izz="0.001"/>
        </inertial>
        <visual>
          <geometry>
            <mesh filename="file://$(find irb120_ros2_gazebo)/meshes/egp64/Schunk Gripper - LEFT FINGER BASE.dae" />
          </geometry>
          <material name="black">
            <color rgba="0 0 0 1"/>
          </material>
        </visual>
        <collision>
          <geometry>
            <mesh filename="file://$(find irb120_ros2_gazebo)/meshes/egp64/Schunk Gripper - LEFT FINGER BASE.dae" />
          </geometry>
          <material name="black" />
        </collision>
      </link>
      
      <joint name="egp64_finger_left_joint" type="prismatic" >
        <parent link="egp64_gripper_base_link" />
        <child link="egp64_finger_left_link" />
        <limit effort="100" lower="-0.001" upper="0.04" velocity="0.2"/>
        <origin xyz="0.01483 -0.00782 0" rpy="0 0 0" />
        <axis xyz="-1 0 0" />
      </joint>
      
      <!-- LEFT FINGERTIP -->
      
      <link name="egp64_fingertip_left_link">
        <inertial>
          <origin xyz="0.03869 -0.0005 0.00093" rpy="0 0 0" />
          <mass value="0.001" />
          <inertia ixx="0.001" ixy="0.0" ixz="0.0" iyy="0.001" iyz="0.0" izz="0.001"/>
        </inertial>
        <visual>
          <geometry>
            <mesh filename="file://$(find irb120_ros2_gazebo)/meshes/egp64/Schunk Gripper - LEFT FINGER.dae" />
          </geometry>
          <material name="silver">
            <color rgba="0.8 0.8 0.8 1"/>
          </material>
        </visual>
        <collision>
          <geometry>
            <mesh filename="file://$(find irb120_ros2_gazebo)/meshes/egp64/Schunk Gripper - LEFT FINGER.dae" />
          </geometry>
          <material name="black"/>
        </collision>
      </link>
      
      <joint name="egp64_fingertip_left_joint" type="fixed" >
        <parent link="egp64_finger_left_link" />
        <child link="egp64_fingertip_left_link" />
        <origin xyz="0.03869 -0.0005 0.00093" rpy="0 0 0"/>
      </joint>

      
      <!-- RIGHT FINGER BASE -->

      <link name="egp64_finger_right_link">
        <inertial>
          <origin xyz="-0.0153 -0.00602 0" rpy="0 0 0" />
          <mass value="0.002" />
          <inertia ixx="0.001" ixy="0.0" ixz="0.0" iyy="0.001" iyz="0.0" izz="0.001"/>
        </inertial>
        <visual>
          <geometry>
            <mesh filename="file://$(find irb120_ros2_gazebo)/meshes/egp64/Schunk Gripper - RIGHT FINGER BASE.dae" />
          </geometry>
          <material name="black"/>
        </visual>
        <collision>
          <geometry>
            <mesh filename="file://$(find irb120_ros2_gazebo)/meshes/egp64/Schunk Gripper - RIGHT FINGER BASE.dae" />
          </geometry>
          <material name="black"/>
        </collision>
      </link>
      
      <joint name="egp64_finger_right_joint" type="prismatic" >
        <parent link="egp64_gripper_base_link" />
        <child link="egp64_finger_right_link" />
        <limit effort="100" lower="-0.001" upper="0.04" velocity="0.2"/>
        <origin xyz="-0.0153 -0.00602 0" rpy="0 0 0" />
        <axis xyz="1 0 0" />
      </joint>
      
      <!-- RIGHT FINGERTIP -->

      <link name="egp64_fingertip_right_link">
        <inertial>
          <origin xyz="-0.01211 -0.00197 0.00093" rpy="0 0 0" />
          <mass value="0.001" />
          <inertia ixx="0.001" ixy="0.0" ixz="0.0" iyy="0.001" iyz="0.0" izz="0.001"/>
        </inertial>
        <visual>
          <geometry>
            <mesh filename="file://$(find irb120_ros2_gazebo)/meshes/egp64/Schunk Gripper - RIGHT FINGER.dae" />
          </geometry>
          <material name="silver" />
        </visual>
        <collision>
          <geometry>
            <mesh filename="file://$(find irb120_ros2_gazebo)/meshes/egp64/Schunk Gripper - RIGHT FINGER.dae" />
          </geometry>
          <material name="black"/>
      </collision>
      </link>
      
      <joint name="egp64_fingertip_right_joint" type="fixed" >
        <parent link="egp64_finger_right_link" />
        <child link="egp64_fingertip_right_link" />
        <origin xyz="-0.01211 -0.00197 0.00093" rpy="0 0 0"/>
      </joint>

      <!-- SMALL CUBE FOR GRIPPER PLUGIN -->

      <link name="EE_egp64">
        <inertial>
          <origin xyz="0 0 0" rpy="0 0 0" />
          <mass value="0.00001" />
          <inertia ixx="0.001" ixy="0.0" ixz="0.0" iyy="0.001" iyz="0.0" izz="0.001"/>
        </inertial>
        <visual>
          <geometry>
            <box size= "0.001 0.001 0.001" />
          </geometry>
        </visual>
      </link>
      
      <joint name="EE_egp64_joint" type="prismatic" >
        <parent link="egp64_gripper_base_link" />
        <child link="EE_egp64" />
        <limit effort="10000" lower="0.0" upper="0.0" velocity="0.0"/>
        <axis xyz="1 0 0" />
        <origin xyz="0.033 -0.018 0.15" rpy="0 0 0"/>
      </joint>

    </xacro:if>
    <!-- === SCHUNK EGP-64 GRIPPER === -->

  </xacro:macro>
</robot>